Workbook

Sheet Q1B Statements
A1: Gloss & Glow — Individual dataset (Student No. 8571260)
A2: Source: Excel formulas in sheet "input" after entering student number in D1
A4: Item | B4: Amount ($)
A5: Owner's Capital, September 1 | B5: 57126
A6: Accounts payable | B6: 7000
A7: Equipment | B7: 35000
A8: Service revenue | B8: 71260
A9: Owner's Drawings | B9: 6000
A10: Insurance expense | B10: 4500
A11: Cash | B11: 61905
A12: Utilities expense | B12: 710
A13: Supplies | B13: 8571
A14: Salaries and wages expense | B14: 5700
A15: Accounts receivable | B15: 8500
A16: Rent expense | B16: 4500
A18: KEY WORKING (how each amount is derived)
A19: Student number D1 = 8571260. Excel MID is 1-indexed.
A20: Owner's Capital Sept 1 = MID(D1,2,5) = 57126
A21: Service revenue = MID(D1,3,5) = 71260
A22: Utilities expense = MID(D1,3,2)*10 = 71*10 = 710
A23: Supplies = MID(D1,1,4) = 8571
A24: Salaries and wages expense = MID(D1,2,2)*100 = 57*100 = 5700
A25: Accounts receivable = MID(D1,1,2)*100 = 85*100 = 8500
A26: Rent expense = (MID(D1,1,1)+1)*500 = (8+1)*500 = 4500
A27: Accounts payable / Equipment / Drawings / Insurance are fixed: 7000 / 35000 / 6000 / 4500
A28: Cash is determined so Assets = Liabilities + Equity for the personalised dataset:
A29: Cash = 61,905 (see balance check below)
... A35: Revenues
A36: Service revenue | C36: 71260
A37: Expenses
A38: Salaries and wages expense | B38: 5700
A39: Rent expense | B39: 4500
A40: Insurance expense | B40: 4500
A41: Utilities expense | B41: 710
A42: Total expenses | C42: 15410
A43: Net income | C43: 55850
A46: Gloss & Glow
A47: Owner's Equity Statement
A48: For the Month Ended September 30, 2027
A49: Owner's Capital, September 1 | C49: 57126
...

Sheet input
A1: Items for Gloss & Glow September 2027 | C1: student number | D1: 8571260
C2: diff balance sheet | D2: =#REF!-#REF!
A3: Owner's Capital, September 1 | B3: =(MID(D1,2,5))*1 | D3: =B3-'input reference'!B1
A4: Accounts payable | B4: =7000 | C4: =B4-'input reference'!B2
A5: Equipment | B5: 35000 | C5: =B5-'input reference'!B3
A6: Service revenue | B6: =(MID(D1,3,5))*1 | C6: =B6-'input reference'!B4
A7: Owner's Drawings | B7: 6000 | C7: =B7-'input reference'!B5
A8: Insurance expense | B8: 4500 | C8: =B8-'input reference'!B6
A9: Cash | B9: =3000+C16 | C9: =B9-'input reference'!B7
A10: Utilities expense | B10: =(MID(D1,3,2))*10 | C10: =B10-'input reference'!B8
A11: Supplies | B11: =(MID(D1,1,4))*1 | C11: =B11-'input reference'!B9
A12: Salaries and wages expense | B12: =(MID(D1,2,2))*100 | C12: =B12-'input reference'!B10
A13: Accounts receivable | B13: =(MID(D1,1,2))*100 | C13: =B13-'input reference'!B11
A14: Rent expense | B14: =((MID(D1,1,1))+1)*500 | C14: =B14-'input reference'!B12
C16: =D3+C6-C8-C10-C12-C14-C7+C4-(C5+C11+C13)

Sheet input reference
A1: Owner's Capital, September 1 | B1: 47000
A2: Accounts payable | B2: 7000
A3: Equipment | B3: 35000
A4: Service revenue | B4: 28000
A5: Owner's Drawings | B5: 6000
A6: Insurance expense | B6: 4500
A7: Cash | B7: 3000
A8: Utilities expense | B8: 700
A9: Supplies | B9: 4800
A10: Salaries and wages expense | B10: 9000
A11: Accounts receivable | B11: 14000
A12: Rent expense | B12: 5000

Sheet income statement and owners ref
A1: Name | I1: Problem 1.3
A2: Section
A3: Date | I3: Divine Designs Co.
B5: (a)
B6: Divine Designs Co.
B7: Income Statement
B8: For the Month Ended June 30, 2022
A9: 1 | B9: Revenues | I9: 1
A10: 2 | C10: Service revenue | H10: =input!C6 | I10: 2
A11: 3 | I11: 3
A12: 4 | I12: 4
A13: 5 | B13: Expenses | I13: 5
A14: 6 | C14: Salaries and wages expense | G14: =input!C12 | I14: 6
A15: 7 | C15: Rent expense | G15: =input!C14 | I15: 7
A16: 8 | C16: Insurance expense | G16: =input!C8 | I16: 8
A17: 9 | C17: Utilities expense | G17: =input!C10 | I17: 9
A18: 10 | D18: Total expenses | H18: =SUM(G14:G17) | I18: 10
A19: 11 | I19: 11
A20: 12 | I20: 12
A21: 13 | I21: 13
A22: 14 | B22: Net Income (Loss) | H22: =H10-H18 | I22: 14
A23: 15 | I23: 15
A24: 16 | I24: 16
A25: 17 | I25: 17
A26: 18 | I26: 18
A27: 19 | I27: 19
A28: 20 | I28: 20
B31: Divine Designs Co.
B32: Owner's Equity Statement
B33: For the Month Ended June 30, 2022
A34: 1 | B34: Owners Capital, September 1 | H34: =input!D3 | I34: 1
A35: 2 | B35: Add: Net income | H35: =H22 | I35: 2
A36: 3 | H36: =H34+H35 | I36: 3
A37: 4 | B37: Less: Drawings | H37: =input!C7 | I37: 4
A38: 5 | B38: Owner's Capital September 30 | H38: =H36-H37 | I38: 5
A39: 6 | I39: 6
A40: 7 | I40: 7
A41: 8 | I41: 8
A42: 9 | I42: 9
A43: 10 | I43: 10

Sheet balance sheet ref
A1: Name | I1: Problem 1.3 Continued
A2: Section
A3: Date | I3: Divine Designs Co.
B5: (a) Continued
B6: Divine Designs Co.
B7: Balance Sheet
B8: 44742
A9: 1 | B9: Assets | I9: 1
A10: 2 | B10: Cash | H10: =input!C9 | I10: 2
A11: 3 | B11: Accounts receivable | H11: =input!C13 | I11: 3
A12: 4 | B12: Supplies | H12: =input!C11 | I12: 4
A13: 5 | B13: Equipment | H13: =input!C5 | I13: 5
A14: 6 | C14: Total Assets | H14: =SUM(H10:H13) | I14: 6
A15: 7 | I15: 7
A16: 8 | I16: 8
A17: 9 | I17: 9
A18: 10 | B18: Liabilities and Owner's Equity | I18: 10
A19: 11 | B19: Liabilities | I19: 11
A20: 12 | C20: Accounts Payable | H20: =input!C4 | I20: 12
A21: 13 | B21: Owner's Equity | I21: 13
A22: 14 | C22: Owner's Capital | H22: ='income statement and owners ref'!H38 | I22: 14
A23: 15 | B23: Total liabilities and owner's equity | H23: =H20+H22 | I23: 15 | K23: =H23-H14
A24: 16 | I24: 16
A25: 17 | I25: 17
A26: 18 | I26: 18
A27: 19 | I27: 19
A28: 20 | I28: 20

Sheet Q2 Cole TB
A1: Mr Cole Printing Shop — Trial Balance 30 Sept 2027 (with inherited opening errors)
A2: Opening AP & Notes Payable were listed as DEBITS in owner spreadsheet — intentional imbalance $24,000
A4: Account | B4: Debit | C4: Credit
A5: Cash at Bank | B5: 33200
A6: Accounts Receivable | B6: 5500
A7: Supplies | B7: 2600
A8: Equipment | B8: 10000
A9: Accounts Payable | B9: 3800
A10: Notes Payable | C10: 2000
A11: Owner's Capital | C11: 30000
A12: Owner's Drawing | B12: 1800
A13: Service Revenue | C13: 6000
A14: Rent Expense | B14: 1800
A15: Salaries and Wages Expense | B15: 2500
A16: Advertising Expense | B16: 800
A17: Totals | B17: 62000 | C17: 38000
A18: Difference (Dr−Cr)=24000 — equals opening imbalance. September journals are balanced ($56,200=$56,200).

Sheet Q3 NI
A1: Illawarra Yacht Club — March 2027 Correct Net Income
A3: Item | B3: Amount
A4: Unadjusted revenue | B4: 9500
A5: Add: unbilled revenue | B5: 1400
A6: Add: unearned now earned | B6: 2600
A7: Correct revenue | B7: 13500
A8: Unadjusted expenses | B8: 4400
A9: Add: depreciation | B9: 2500
A10: Add: accrued interest | B10: 1500
A11: Add: insurance expired | B11: 600
A12: Correct expenses | B12: 9000
A13: Correct net income | B13: 4500
A14: Answer: $4,500

Sheet Q4 Adjusted TB
A1: Rodney Fitness — Adjusted Trial Balance June 30, 2027
A3: Account | B3: Debit | C3: Credit
A4: Cash | B4: 6000
A5: Accounts Receivable | B5: 7500
A6: Supplies | B6: 950
A7: Prepaid Insurance | B7: 3850
A8: Equipment | B8: 16150
A9: Accumulated Depreciation—Equipment | C9: 350
A10: Accounts Payable | C10: 3775
A11: Salaries and Wages Payable | C11: 2100
A12: Unearned Service Revenue | C12: 2500
A13: Owner's Capital | C13: 23750
A14: Service Revenue | C14: 9900
A15: Supplies Expense | B15: 850
A16: Depreciation Expense | B16: 350
A17: Insurance Expense | B17: 350
A18: Salaries and Wages Expense | B18: 5100
A19: Rent Expense | B19: 1000
A20: Utilities Expense | B20: 275
A21: Totals | B21: 42375 | C21: 42375
A23: Adjusting entries detail is in Assessment1A_Worked_Solutions.docx (Q4).
